<!DOCTYPE html>
<html lang="en">
<head>
	<meta charset="UTF-8">
	<title>for Async</title>
</head>
<body>
	<script>
		/*
		var a = [];
		for (let i = 0; i < 10; i++) {
		  a[i] = function () {
		    console.log(i);
		  };
		}
		a[6]();
		console.log(a);
		
		

		//从js的错误处理机制切入，理解es6的promise
		try{
			console.log(fdsafds);
		}catch(error){
			alert(error.message);
			//错误被放进这里打印出来，而不是在浏览器的开发者工具里红字显示。我们应该把所有可能会抛出错误的代码都放在 try 语句块中，而把那些用于错误处理的代码放在 catch 块中
			if (error instanceof TypeError){
				//处理类型错误
				alert(error.constructor.name);
			} else if (error instanceof ReferenceError){
				//处理引用错误
				alert(error.constructor.name);
			} else {
				//处理其他类型的错误
				alert(error.constructor.name);
			}
		}
		
		// throw 操作符，用于随时抛出自定义错误。抛出错误时，必须要给 throw 操作符指定一个值，这个值是什么类型，没有要求
		//比如：我们写bind函数模拟，如果调用_bind()的不是一个函数，那就可以主动抛出一个错误，像浏览器一样显示红字报错：
		function testThrow(val){
			if(typeof val !== 'string'){
				throw new Error('testThrow():arguments need string')
			}
		};
		try{
			testThrow({});
		}catch(error){
			console.log('err_msg=='+error.message);
		}
		
		console.log('错误被捕获了，代码可以继执行');
		//try-catch用于捕获错误，throw用于主动抛出错误
		//回调函数
		
		// function main(cb){
		// 	var obj = {};
		// 	cb(obj);
		// }
		// function branch(val){
		// 	if(typeof val !=='number'){
		// 		throw new Error('branch(): argument need number');
		// 	}
		// 	var rslt = 0;
		// 	for(var i = 0;i<1000000000;i++){
		// 		rslt+=i;
		// 	}
		// };
		// try{
		// 	main(branch);
		// }catch(error){
		// 	console.log('err_msg=='+error.message);
		// };


		function main(cb){
			var obj = {};
			setTimeout(function(){
				cb(obj);
			}, 0);
			
		}
		function branch(val){
			if(typeof val !=='number'){
				throw new Error('branch(): argument need number');
			}
			var rslt = 0;
			for(var i = 0;i<1000000000;i++){
				rslt+=i;
			}
		};
		try{
			main(branch);
		}catch(error){
			console.log('err_msg=='+error.message);
		};

		//Promise
		function timeout(ms){
			return new Promise((resolve,reject)=>{
				setTimeout(resolve, ms, 'done');//done是对应then里的value
			});
		};
		timeout(100).then((value)=>{
			console.log(value);
		});

		let promise = new Promise(function(resolve, reject) {
		  console.log('Promise');
		  reject('reject传参');//后面的异步是执行resolved还是rejected，依据这里的主动触发
		});

		promise.then(function() {
		  console.log('resolved.');
		},function(err){
			console.log(err); //reject传参
			console.log('rejected.');
		});

		console.log('Hi!');
		
		
		function imgAsync(url){
			return new Promise((resolve,reject)=>{
				let image = new Image();
				image.onload = function(){
					resolve(image);
				}
				image.onerror = function(){
					reject(new Error('Could not load image at ' + url));
				}
				image.src = url;
			})
		}
		imgAsync('');


		//resolve的传参是另一个Promise的实例
		console.log(parseInt(new Date().getTime()/1000));
		const p1 = new Promise(function (resolve, reject) {
		  setTimeout(() => {
		  	console.log(parseInt(new Date().getTime()/1000));
		  	console.log('p1开始reject');
		  	reject(new Error('fail'));
		  	//resolve('p1现在的状态是resolve了');
		  	console.log('p1完成reject');
		  }, 0)
		})

		const p2 = new Promise(function (resolve, reject) {
		  setTimeout(() => {
		  	console.log(parseInt(new Date().getTime()/1000));
		  	console.log('p2开始resolve');
		  	resolve(p1);
		  	console.log('p2完成resolve');
		  }, 1000)
		})

		p2.then(result => {
			console.log('进来的状态是resolve');
			console.log(result)}
		).catch(error => {
			console.log('进来的状态是reject');
		  	console.log(error)}
		);
		//1515464452
		//1515464453
		//p2开始resolve
		//p2完成resolve
		//1515464455
		//p1开始reject
		//p1完成reject
		//进来的状态是reject
		//Error: fail

		//一个异步操作的结果是返回(resolve)另一个异步操作。这时p1的状态决定了p2的状态。如果p1的状态是pending，那么p2的回调函数就会等待p1的状态改变；如果p1的状态已经是resolved或者rejected，那么p2的回调函数将会立刻执行。而且p2最后执行哪个状态的回调也以p1为准
		
		let b = new Promise(
		  function(resolve, reject) {
		    console.log(5)
		    setTimeout(() => {
		    	resolve('b is done');
		    	console.log(6)
		    }, 0)
		  }
		)
		let a = new Promise(
		  function(resolve, reject) {
		    console.log(1)
		    setTimeout(() => console.log(2), 0)
		    console.log(3)
		    console.log(4)
		    resolve(b);
		  }
		)
		
		a.then(v => {
			console.log(v)
		  	console.log(8)
		})

		console.log(7);
		
		//5,1,3,4,7,6,b is done,8,2
		//任务执行顺序还是先同步，打印5,1,3,4,7;再异步，这里有个坎，异步a返回的是另一个异步b，所以a.then()要等到作为参数的异步b完成才能执行。同时异步b的resolve是写在定时器里的，那只能等定时器操作完才能走进a.then(),所以先打印6，再打印b is done,8,到这里异步才算执行完;最后打印定时器里的东西 2
		
		//当采用采用链式的then()语句时，Promise.prototype.catch如何捕获错误
		let testCatch = function(state,goon){
			return new Promise((resolve, reject)=>{
				if(state==='ok'){
					resolve(goon);
				}else{
					reject('stop1');
				}
			});
		};
		function test(a,b){
			testCatch(a,b).then((v)=>{
				if(v==='ok'){
					console.log(v);
				}else{
					console.log(x);//x未定义
				}
			}).catch((err)=>{
				console.log(err);
			});
		};
		test('ok','no');//x is not defined
		test('no','no');//stop1
		//catch可以捕获来自最初Promise实例的错误，也可以捕获来自then方法的错误。
		
		//Promise 对象的错误具有“冒泡”性质，会一直向后传递，直到被catch捕获为止。如果没有使用catch方法指定错误处理的回调函数，Promise 对象抛出的错误不会传递到外层代码，而是默默地被promise吃掉了。从而不会阻塞脚本的继续进行。

		//错误无法捕获的情况
		const promise = new Promise(function (resolve, reject) {
		  resolve('ok');
		  setTimeout(function () { throw new Error('test') }, 0);//定时器等异步执行完了才调用，这是Promise运行已经结束，错误就无法捕获了。
		});
		promise.then(function (value) { console.log(value) }).catch((err)=>{
			console.log(err);
		});
		setTimeout(function () { console.log('抛错到外部，外部代码继续执行'); }, 0);

		//如果catch里也抛出一个错误，那就再写个catch去捕获
		

		const p1 = new Promise((resolve, reject) => {
		  resolve('hello');
		})
		.then(result => result)
		.catch(e => e);

		const p2 = new Promise((resolve, reject) => {
		  throw new Error('报错了');
		})
		.then(result => result)
		.catch(e => {
			e;
			x
		});

		Promise.all([p1, p2])
		.then(result => console.log(result))
		.catch(e => console.log(e));
		// ["hello", Error: 报错了]
		

		//Generator
		function* helloWorldGenerator() {
		  yield 'hello';
		  yield 'world';
		  return 'ending';
		}

		var hw = helloWorldGenerator();
		console.log(hw);
		console.log(hw.next());//{value: "hello", done: false}
		console.log(hw.next());//{value: "world", done: false}
		console.log(hw.next());//{value: "ending", done: true}
		console.log(hw.next());//{value: undefined, done: true}
		//Generator 函数开始执行，直到遇到第一个yield表达式为止,如果最后一句不是return而是yield，那要等第四次next()才会让done变为true。



		function* gen() {
			yield  123 + 456;
		}
		var hw2 = gen();
		console.log(hw2.next());//{value: 579, done: false}
		console.log(hw2.next());//{value: undefined, done: true}

		function* f2() {
		  console.log('执行了！')
		}

		var generator = f2();

		setTimeout(function () {
		  generator.next()
		}, 2000);
		
		
		//next()传参
		function* demo() {
			console.log('执行了demo');
		  	let input = yield 1; // yield表达式本身没有返回值，或者说总是返回undefined
		  	console.log(input);
		  
		}
		var hw3 = demo();
		//第一步
		hw3.next(); //'执行了demo'
		//第二步(不传参)
		//hw3.next(); //undefined
		//console.log(hw3.next()); //{value: undefined, done: true}
		//第二步(传参)
		//next方法可以带一个参数，该参数就会被当作上一个yield表达式的返回值。所以input= true;
		//hw3.next(true); //true
		//console.log(hw3.next(true)); //{value: undefined, done: true}

		function* f() {
		  	for(var i = 0; true; i++) {
		    	var reset = yield i;
		    	if(reset) { i = -1; }
		  	}
		}

		var g = f();
		//第一步从函数顶部到第一个yield
		console.log(g.next()); // { value: 0, done: false }
		//第二步从上一个yield（第一个）到新的yield（第二个）
		console.log(g.next()); // { value: 1, done: false }
		console.log(g.next());
		//第三步，如果不传true；应该是{ value: 2, done: false }，因为上一个yield的返回值是1，依据for循环，当前yield后作为next()执行后对象value值的值应该是2；但是因为传了个true，使得yield i的返回值是true，所以reset是true，所以上一个yield的返回值i= -1，所以当前yield后作为next()执行后对象value值的值变成了-1+1=0。
		console.log(g.next(true)); // { value: 0, done: false }
		
		function* foo1(x) {
			console.log(x);
		  	var y = 2 * (yield (x + 1));
		  	console.log(y);
		  	var z = yield (y / 3);
		  	console.log(z);
		  	return (x + y + z);
		}

		var a = foo1(5);
		//第一步，从函数顶部到第一个yield表达式结束为止，5+1=6；
		a.next() // Object{value:6, done:false}
		//第二步，从第一个yield开始到第二个yield表达式结束，因为yield表达式本身只返回undefined，所以y=2*undefined=NaN;同时，第二个yield表达式后面的值NaN/3 =NaN
		a.next() // Object{value:NaN, done:false}
		//第三步，从第二个yield开始到return语句结束，因为yield表达式本身只返回undefined，所以z=undefined，同时return返回5+NaN+undefined=NaN，结束！done:true
		a.next() // Object{value:NaN, done:true}

		var b = foo1(5);
		//第一步，从函数顶部到第一个yield表达式结束为止，5+1=6;
		b.next() // { value:6, done:false }
		//第二步，从第一个yield开始到第二个yield表达式结束，因为yield表达式本身只返回undefined，但是由于next()传参12，所以(yield (x + 1))的返回值是12，y=2*12=24;同时，第二个yield表达式后面的值24/3 =8；
		b.next(12) // { value:8, done:false }
		//第三步，从第二个yield开始到return语句结束，因为yield表达式本身只返回undefined，所以yield (y / 3)的返回值是13，z=13，同时return返回5+24+13=42，结束！done:true
		b.next(13) // { value:42, done:true }

		//值得注意的是：V8 引擎直接忽略第一次使用next方法时的参数，只有从第二次使用next方法开始，参数才是有效的

		function* dataConsumer() {
		  console.log('Started');
		  console.log(`1. ${yield}`);
		  console.log(`2. ${yield}`);
		  return 'result';
		}

		let genObj = dataConsumer();
		// Started
		console.log(genObj.next());// { value:'undefined', done:false }
		//----- 1. a
		console.log(genObj.next('a'));// { value:'undefined', done:false }
		//----- 2. b
		console.log(genObj.next('b'));// { value:'result', done:true }
		
		//Generator 函数开始执行，直到遇到第一个yield表达式为止,而不是yield所在那行代码执行完。所以console.log()打印出1. a是在第二次next()之前。
		

		//Generator.prototype.throw()
		var gen1 = function* gen1(){
		  try {
		    yield console.log('a');
		  } catch (e) {
		    // ...
		  }
		  yield console.log('b');
		  yield console.log('c');
		}

		var g = gen1();
		// a
		g.next() // {value: undefined, done: false}
		// b
		g.throw() // {value: undefined, done: false}
		// c
		g.next() // {value: undefined, done: false}
		g.next() // {value: undefined, done: true}
		//throw方法被捕获以后，自动执行了一次next方法
		
		function* gen3() {
		  var x = yield 3;
		  var y = x.toUpperCase();
		  yield y;
		}

		var g3 = gen3();

		g3.next(); // { value:3, done:false }

		try {
		    g3.next(42);
		} catch (err) {
		  console.log(err);
		}
		console.log(g3.next());
		//Generator 函数体内抛出的错误未被内部try-catch捕获（不是通过Generator.prototype.throw()抛出的错误），会使得Generator 函数执行提前结束。

		//Generator.prototype.return()
		function* numbers () {
		  yield 1;
		  try {
		    yield 2;
		    yield 3;
		  } finally {
		    yield 4;
		    yield 5;
		  }
		  yield 6;
		}
		var g = numbers();
		g.next() // { value: 1, done: false }
		g.next() // { value: 2, done: false }
		g.return(7) // { value: 4, done: false }
		g.next() // { value: 5, done: false }
		g.next() // { value: 7, done: true }
		//调用return()后，在跳过yield 3;进入finally代码块内执行，执行完了立马生效刚才调用的return方法并结束掉generator。所以打印了 { value: 7, done: true }而不是 { value: 6, done: false }
*/
		//yield*表达式
		function* item1(){
			yield 'a';
			return 'b';
		}
		function* gen4(){
			yield 1;
			var v = yield* item1();
			console.log( "v: " + v );
			yield 2;
			return 3;
		}
		var g4 = gen4();
		console.log(g4.next());//{value: 1, done: false}
		console.log(g4.next());//{value: a, done: false}
		//v: b
		console.log(g4.next()); //{value: 2, done: false}
		console.log(g4.next()); //{value: 3, done: true}
		//如果有return语句，相当于只取yield表达式内容，然后next()只顺序执行两个generator里的yield。return返回的东西可以被用来赋值。

		function* gen5(){
		  yield* ["a", "b", "c"];
		}
		var g5 = gen5();
		console.log(g5.next()); // { value:"a", done:false }
		console.log(g5.next()); // { value:"b", done:false }
		console.log(g5.next()); // { value:"c", done:false }
		console.log(g5.next()); // { value:undefined, done:true }

		function* F() {
		  this.a = 1;
		  yield this.b = 2;
		  yield this.c = 3;
		}
		var obj = {};
		var f = F.call(obj);

		f.next();  // Object {value: 2, done: false}
		f.next();  // Object {value: 3, done: false}
		f.next();  // Object {value: undefined, done: true}

		obj.a // 1
		obj.b // 2
		obj.c // 3

		console.log(obj.__proto__===Object.prototype);//true

		//generator 与状态机
		var clock = function* () {
		  while (true) {
		    console.log('Tick!');
		    yield;
		    console.log('Tock!');
		    yield;
		  }
		};
		var c = clock();
		console.log(c.value);
		c.next();
		c.next();
		c.next();
		c.next();
		//whild(true){代码块会无限执行下去}，就好比函数体内有N多个console和yield。由于generator是遍历器，执行靠next,所以不会让浏览器崩溃，





	</script>
</body>
</html>